[START] 11/10/2025  9:00:02.06 
Running: venv\Scripts\python.exe manage.py calibration_reminders --days 30 --settings=core.settings_maintenance 
Traceback (most recent call last):
  File "C:\dev\bakim_kalibrasyon\venv\Lib\site-packages\django\db\backends\utils.py", line 106, in _execute
    return self.cursor.execute(sql, params)
           ^^^^^^^^^^^^^^^^^^^^^^^^^^^^^^^^
  File "C:\dev\bakim_kalibrasyon\venv\Lib\site-packages\django\db\backends\sqlite3\base.py", line 361, in execute
    return super().execute(query, params)
           ^^^^^^^^^^^^^^^^^^^^^^^^^^^^^^
sqlite3.OperationalError: no such table: maintenance_calibrationrecord

The above exception was the direct cause of the following exception:

Traceback (most recent call last):
  File "C:\dev\bakim_kalibrasyon\manage.py", line 26, in <module>
    main()
  File "C:\dev\bakim_kalibrasyon\manage.py", line 22, in main
    execute_from_command_line(sys.argv)
  File "C:\dev\bakim_kalibrasyon\venv\Lib\site-packages\django\core\management\__init__.py", line 443, in execute_from_command_line
    utility.execute()
  File "C:\dev\bakim_kalibrasyon\venv\Lib\site-packages\django\core\management\__init__.py", line 437, in execute
    self.fetch_command(subcommand).run_from_argv(self.argv)
  File "C:\dev\bakim_kalibrasyon\venv\Lib\site-packages\django\core\management\base.py", line 417, in run_from_argv
    self.execute(*args, **cmd_options)
  File "C:\dev\bakim_kalibrasyon\venv\Lib\site-packages\django\core\management\base.py", line 461, in execute
    output = self.handle(*args, **options)
             ^^^^^^^^^^^^^^^^^^^^^^^^^^^^^
  File "C:\dev\bakim_kalibrasyon\maintenance\management\commands\calibration_reminders.py", line 92, in handle
    latest_map = _select_latest_record_map()
                 ^^^^^^^^^^^^^^^^^^^^^^^^^^^
  File "C:\dev\bakim_kalibrasyon\maintenance\management\commands\calibration_reminders.py", line 35, in _select_latest_record_map
    for rec in qs:
  File "C:\dev\bakim_kalibrasyon\venv\Lib\site-packages\django\db\models\query.py", line 385, in __iter__
    self._fetch_all()
  File "C:\dev\bakim_kalibrasyon\venv\Lib\site-packages\django\db\models\query.py", line 1950, in _fetch_all
    self._result_cache = list(self._iterable_class(self))
                         ^^^^^^^^^^^^^^^^^^^^^^^^^^^^^^^^
  File "C:\dev\bakim_kalibrasyon\venv\Lib\site-packages\django\db\models\query.py", line 92, in __iter__
    results = compiler.execute_sql(
              ^^^^^^^^^^^^^^^^^^^^^
  File "C:\dev\bakim_kalibrasyon\venv\Lib\site-packages\django\db\models\sql\compiler.py", line 1624, in execute_sql
    cursor.execute(sql, params)
  File "C:\dev\bakim_kalibrasyon\venv\Lib\site-packages\django\db\backends\utils.py", line 123, in execute
    return super().execute(sql, params)
           ^^^^^^^^^^^^^^^^^^^^^^^^^^^^
  File "C:\dev\bakim_kalibrasyon\venv\Lib\site-packages\django\db\backends\utils.py", line 80, in execute
    return self._execute_with_wrappers(
           ^^^^^^^^^^^^^^^^^^^^^^^^^^^^
  File "C:\dev\bakim_kalibrasyon\venv\Lib\site-packages\django\db\backends\utils.py", line 93, in _execute_with_wrappers
    return executor(sql, params, many, context)
           ^^^^^^^^^^^^^^^^^^^^^^^^^^^^^^^^^^^^
  File "C:\dev\bakim_kalibrasyon\venv\Lib\site-packages\django\db\backends\utils.py", line 101, in _execute
    with self.db.wrap_database_errors:
  File "C:\dev\bakim_kalibrasyon\venv\Lib\site-packages\django\db\utils.py", line 92, in __exit__
    raise dj_exc_value.with_traceback(traceback) from exc_value
  File "C:\dev\bakim_kalibrasyon\venv\Lib\site-packages\django\db\backends\utils.py", line 106, in _execute
    return self.cursor.execute(sql, params)
           ^^^^^^^^^^^^^^^^^^^^^^^^^^^^^^^^
  File "C:\dev\bakim_kalibrasyon\venv\Lib\site-packages\django\db\backends\sqlite3\base.py", line 361, in execute
    return super().execute(query, params)
           ^^^^^^^^^^^^^^^^^^^^^^^^^^^^^^
django.db.utils.OperationalError: no such table: maintenance_calibrationrecord
ExitCode=1 
[END] 11/10/2025  9:00:03.09 
 
